[2024-01-12T17:36:38.465+0000] {taskinstance.py:1957} INFO - Dependencies all met for dep_context=non-requeueable deps ti=<TaskInstance: extract_fdic_ncua.fdic.extract_fdic_financials manual__2024-01-12T17:36:37.565821+00:00 [queued]>
[2024-01-12T17:36:38.471+0000] {taskinstance.py:1957} INFO - Dependencies all met for dep_context=requeueable deps ti=<TaskInstance: extract_fdic_ncua.fdic.extract_fdic_financials manual__2024-01-12T17:36:37.565821+00:00 [queued]>
[2024-01-12T17:36:38.471+0000] {taskinstance.py:2171} INFO - Starting attempt 1 of 1
[2024-01-12T17:36:38.478+0000] {taskinstance.py:2192} INFO - Executing <Task(_PythonDecoratedOperator): fdic.extract_fdic_financials> on 2024-01-12 17:36:37.565821+00:00
[2024-01-12T17:36:38.482+0000] {standard_task_runner.py:60} INFO - Started process 6546 to run task
[2024-01-12T17:36:38.485+0000] {standard_task_runner.py:87} INFO - Running: ['***', 'tasks', 'run', 'extract_fdic_ncua', 'fdic.extract_fdic_financials', 'manual__2024-01-12T17:36:37.565821+00:00', '--job-id', '77', '--raw', '--subdir', 'DAGS_FOLDER/fdic-ncua-ingest.py', '--cfg-path', '/tmp/tmp5fd3wf76']
[2024-01-12T17:36:38.487+0000] {standard_task_runner.py:88} INFO - Job 77: Subtask fdic.extract_fdic_financials
[2024-01-12T17:36:38.538+0000] {task_command.py:423} INFO - Running <TaskInstance: extract_fdic_ncua.fdic.extract_fdic_financials manual__2024-01-12T17:36:37.565821+00:00 [running]> on host c111cf247bc6
[2024-01-12T17:36:38.583+0000] {taskinstance.py:2481} INFO - Exporting env vars: AIRFLOW_CTX_DAG_OWNER='***' AIRFLOW_CTX_DAG_ID='extract_fdic_ncua' AIRFLOW_CTX_TASK_ID='fdic.extract_fdic_financials' AIRFLOW_CTX_EXECUTION_DATE='2024-01-12T17:36:37.565821+00:00' AIRFLOW_CTX_TRY_NUMBER='1' AIRFLOW_CTX_DAG_RUN_ID='manual__2024-01-12T17:36:37.565821+00:00'
[2024-01-12T17:36:38.584+0000] {taskinstance.py:2699} ERROR - Task failed with exception
Traceback (most recent call last):
  File "/home/airflow/.local/lib/python3.8/site-packages/airflow/models/taskinstance.py", line 433, in _execute_task
    result = execute_callable(context=context, **execute_callable_kwargs)
  File "/home/airflow/.local/lib/python3.8/site-packages/airflow/decorators/base.py", line 242, in execute
    return_value = super().execute(context)
  File "/home/airflow/.local/lib/python3.8/site-packages/airflow/operators/python.py", line 199, in execute
    return_value = self.execute_callable()
  File "/home/airflow/.local/lib/python3.8/site-packages/airflow/operators/python.py", line 216, in execute_callable
    return self.python_callable(*self.op_args, **self.op_kwargs)
  File "/opt/airflow/dags/fdic-ncua-ingest.py", line 51, in extract_fdic_financials
    insert_to_pg(hook=pg_hook, schema='raw', table='fdic_financials', data=get_fdic_data("/financials"))
  File "/opt/airflow/dags/utils/core/fdic/fdic.py", line 43, in get_fdic_data
    response = fdic_request(endpoint, offset=offset, limit=limit)
  File "/opt/airflow/dags/utils/core/fdic/fdic.py", line 15, in fdic_request
    today = datetime.today().strftime('%Y%m%d')
AttributeError: module 'datetime' has no attribute 'today'
[2024-01-12T17:36:38.591+0000] {taskinstance.py:1138} INFO - Marking task as FAILED. dag_id=extract_fdic_ncua, task_id=fdic.extract_fdic_financials, execution_date=20240112T173637, start_date=20240112T173638, end_date=20240112T173638
[2024-01-12T17:36:38.598+0000] {standard_task_runner.py:107} ERROR - Failed to execute job 77 for task fdic.extract_fdic_financials (module 'datetime' has no attribute 'today'; 6546)
[2024-01-12T17:36:38.618+0000] {local_task_job_runner.py:234} INFO - Task exited with return code 1
[2024-01-12T17:36:38.628+0000] {taskinstance.py:3281} INFO - 0 downstream tasks scheduled from follow-on schedule check
