[2024-01-13T18:10:15.139+0000] {taskinstance.py:1957} INFO - Dependencies all met for dep_context=non-requeueable deps ti=<TaskInstance: fdic_ncua_ingest.fdic_ncua.ncua_extract.extract_ncua_call_report_data manual__2024-01-13T18:10:11.666403+00:00 [queued]>
[2024-01-13T18:10:15.144+0000] {taskinstance.py:1957} INFO - Dependencies all met for dep_context=requeueable deps ti=<TaskInstance: fdic_ncua_ingest.fdic_ncua.ncua_extract.extract_ncua_call_report_data manual__2024-01-13T18:10:11.666403+00:00 [queued]>
[2024-01-13T18:10:15.144+0000] {taskinstance.py:2171} INFO - Starting attempt 1 of 1
[2024-01-13T18:10:15.153+0000] {taskinstance.py:2192} INFO - Executing <Task(_PythonDecoratedOperator): fdic_ncua.ncua_extract.extract_ncua_call_report_data> on 2024-01-13 18:10:11.666403+00:00
[2024-01-13T18:10:15.157+0000] {standard_task_runner.py:60} INFO - Started process 3186 to run task
[2024-01-13T18:10:15.162+0000] {standard_task_runner.py:87} INFO - Running: ['***', 'tasks', 'run', 'fdic_ncua_ingest', 'fdic_ncua.ncua_extract.extract_ncua_call_report_data', 'manual__2024-01-13T18:10:11.666403+00:00', '--job-id', '248', '--raw', '--subdir', 'DAGS_FOLDER/fdic-ncua-ingest.py', '--cfg-path', '/tmp/tmpe2fhyrnn']
[2024-01-13T18:10:15.163+0000] {standard_task_runner.py:88} INFO - Job 248: Subtask fdic_ncua.ncua_extract.extract_ncua_call_report_data
[2024-01-13T18:10:15.206+0000] {task_command.py:423} INFO - Running <TaskInstance: fdic_ncua_ingest.fdic_ncua.ncua_extract.extract_ncua_call_report_data manual__2024-01-13T18:10:11.666403+00:00 [running]> on host c111cf247bc6
[2024-01-13T18:10:15.250+0000] {taskinstance.py:2481} INFO - Exporting env vars: AIRFLOW_CTX_DAG_OWNER='***' AIRFLOW_CTX_DAG_ID='fdic_ncua_ingest' AIRFLOW_CTX_TASK_ID='fdic_ncua.ncua_extract.extract_ncua_call_report_data' AIRFLOW_CTX_EXECUTION_DATE='2024-01-13T18:10:11.666403+00:00' AIRFLOW_CTX_TRY_NUMBER='1' AIRFLOW_CTX_DAG_RUN_ID='manual__2024-01-13T18:10:11.666403+00:00'
[2024-01-13T18:10:15.721+0000] {taskinstance.py:2699} ERROR - Task failed with exception
Traceback (most recent call last):
  File "/home/airflow/.local/lib/python3.8/site-packages/airflow/models/taskinstance.py", line 433, in _execute_task
    result = execute_callable(context=context, **execute_callable_kwargs)
  File "/home/airflow/.local/lib/python3.8/site-packages/airflow/decorators/base.py", line 242, in execute
    return_value = super().execute(context)
  File "/home/airflow/.local/lib/python3.8/site-packages/airflow/operators/python.py", line 199, in execute
    return_value = self.execute_callable()
  File "/home/airflow/.local/lib/python3.8/site-packages/airflow/operators/python.py", line 216, in execute_callable
    return self.python_callable(*self.op_args, **self.op_kwargs)
  File "/opt/airflow/dags/fdic-ncua-ingest.py", line 40, in extract_ncua_call_report_data
    ncua_call_report_to_s3(s3_hook, lq_year, lq_month)
  File "/opt/airflow/dags/utils/core/ncua/ncua.py", line 15, in ncua_call_report_to_s3
    raise Exception(f"Request failed with status {response.status_code}. Check that the url {url} exists.")
Exception: Request failed with status 404. Check that the url https://ncua.gov/files/publications/analysis/call-report-data-2023-12.zip exists.
[2024-01-13T18:10:15.753+0000] {taskinstance.py:1138} INFO - Marking task as FAILED. dag_id=fdic_ncua_ingest, task_id=fdic_ncua.ncua_extract.extract_ncua_call_report_data, execution_date=20240113T181011, start_date=20240113T181015, end_date=20240113T181015
[2024-01-13T18:10:15.774+0000] {standard_task_runner.py:107} ERROR - Failed to execute job 248 for task fdic_ncua.ncua_extract.extract_ncua_call_report_data (Request failed with status 404. Check that the url https://ncua.gov/files/publications/analysis/call-report-data-2023-12.zip exists.; 3186)
[2024-01-13T18:10:15.821+0000] {local_task_job_runner.py:234} INFO - Task exited with return code 1
[2024-01-13T18:10:15.842+0000] {taskinstance.py:3281} INFO - 0 downstream tasks scheduled from follow-on schedule check
