[2024-01-13T19:13:00.827+0000] {taskinstance.py:1957} INFO - Dependencies all met for dep_context=non-requeueable deps ti=<TaskInstance: fdic_ncua_ingest.check_for_new_fdic_data manual__2024-01-13T19:12:59.701289+00:00 [queued]>
[2024-01-13T19:13:00.832+0000] {taskinstance.py:1957} INFO - Dependencies all met for dep_context=requeueable deps ti=<TaskInstance: fdic_ncua_ingest.check_for_new_fdic_data manual__2024-01-13T19:12:59.701289+00:00 [queued]>
[2024-01-13T19:13:00.832+0000] {taskinstance.py:2171} INFO - Starting attempt 1 of 1
[2024-01-13T19:13:00.847+0000] {taskinstance.py:2192} INFO - Executing <Task(_PythonDecoratedOperator): check_for_new_fdic_data> on 2024-01-13 19:12:59.701289+00:00
[2024-01-13T19:13:00.851+0000] {standard_task_runner.py:60} INFO - Started process 4218 to run task
[2024-01-13T19:13:00.876+0000] {standard_task_runner.py:87} INFO - Running: ['***', 'tasks', 'run', 'fdic_ncua_ingest', 'check_for_new_fdic_data', 'manual__2024-01-13T19:12:59.701289+00:00', '--job-id', '282', '--raw', '--subdir', 'DAGS_FOLDER/fdic-ncua-ingest.py', '--cfg-path', '/tmp/tmpa8b5zh8r']
[2024-01-13T19:13:00.878+0000] {standard_task_runner.py:88} INFO - Job 282: Subtask check_for_new_fdic_data
[2024-01-13T19:13:00.922+0000] {task_command.py:423} INFO - Running <TaskInstance: fdic_ncua_ingest.check_for_new_fdic_data manual__2024-01-13T19:12:59.701289+00:00 [running]> on host c111cf247bc6
[2024-01-13T19:13:00.975+0000] {taskinstance.py:2481} INFO - Exporting env vars: AIRFLOW_CTX_DAG_OWNER='***' AIRFLOW_CTX_DAG_ID='fdic_ncua_ingest' AIRFLOW_CTX_TASK_ID='check_for_new_fdic_data' AIRFLOW_CTX_EXECUTION_DATE='2024-01-13T19:12:59.701289+00:00' AIRFLOW_CTX_TRY_NUMBER='1' AIRFLOW_CTX_DAG_RUN_ID='manual__2024-01-13T19:12:59.701289+00:00'
[2024-01-13T19:13:00.976+0000] {taskinstance.py:2699} ERROR - Task failed with exception
Traceback (most recent call last):
  File "/home/airflow/.local/lib/python3.8/site-packages/airflow/models/taskinstance.py", line 433, in _execute_task
    result = execute_callable(context=context, **execute_callable_kwargs)
  File "/home/airflow/.local/lib/python3.8/site-packages/airflow/decorators/base.py", line 242, in execute
    return_value = super().execute(context)
  File "/home/airflow/.local/lib/python3.8/site-packages/airflow/operators/python.py", line 199, in execute
    return_value = self.execute_callable()
  File "/home/airflow/.local/lib/python3.8/site-packages/airflow/operators/python.py", line 216, in execute_callable
    return self.python_callable(*self.op_args, **self.op_kwargs)
  File "/opt/airflow/dags/fdic-ncua-ingest.py", line 131, in t__check_for_new_fdic_data
    found_new_data = check_for_new_fdic_data(hook=pg_hook, today=today, last_quarter_dt=last_quarter)
TypeError: check_for_new_fdic_data() got an unexpected keyword argument 'last_quarter_dt'
[2024-01-13T19:13:00.983+0000] {taskinstance.py:1138} INFO - Marking task as FAILED. dag_id=fdic_ncua_ingest, task_id=check_for_new_fdic_data, execution_date=20240113T191259, start_date=20240113T191300, end_date=20240113T191300
[2024-01-13T19:13:00.989+0000] {standard_task_runner.py:107} ERROR - Failed to execute job 282 for task check_for_new_fdic_data (check_for_new_fdic_data() got an unexpected keyword argument 'last_quarter_dt'; 4218)
[2024-01-13T19:13:00.994+0000] {local_task_job_runner.py:234} INFO - Task exited with return code 1
[2024-01-13T19:13:01.012+0000] {taskinstance.py:3281} INFO - 0 downstream tasks scheduled from follow-on schedule check
