[2024-01-13T00:52:16.942+0000] {taskinstance.py:1957} INFO - Dependencies all met for dep_context=non-requeueable deps ti=<TaskInstance: fdic_ncua_data_marts.trigger_metrics_dag manual__2024-01-13T00:52:16.320019+00:00 [queued]>
[2024-01-13T00:52:16.954+0000] {taskinstance.py:1957} INFO - Dependencies all met for dep_context=requeueable deps ti=<TaskInstance: fdic_ncua_data_marts.trigger_metrics_dag manual__2024-01-13T00:52:16.320019+00:00 [queued]>
[2024-01-13T00:52:16.955+0000] {taskinstance.py:2171} INFO - Starting attempt 1 of 1
[2024-01-13T00:52:16.969+0000] {taskinstance.py:2192} INFO - Executing <Task(TriggerDagRunOperator): trigger_metrics_dag> on 2024-01-13 00:52:16.320019+00:00
[2024-01-13T00:52:16.974+0000] {standard_task_runner.py:60} INFO - Started process 13521 to run task
[2024-01-13T00:52:16.980+0000] {standard_task_runner.py:87} INFO - Running: ['***', 'tasks', 'run', 'fdic_ncua_data_marts', 'trigger_metrics_dag', 'manual__2024-01-13T00:52:16.320019+00:00', '--job-id', '210', '--raw', '--subdir', 'DAGS_FOLDER/fdic-ncua-data-marts.py', '--cfg-path', '/tmp/tmp2ij15v8n']
[2024-01-13T00:52:16.982+0000] {standard_task_runner.py:88} INFO - Job 210: Subtask trigger_metrics_dag
[2024-01-13T00:52:17.021+0000] {task_command.py:423} INFO - Running <TaskInstance: fdic_ncua_data_marts.trigger_metrics_dag manual__2024-01-13T00:52:16.320019+00:00 [running]> on host c111cf247bc6
[2024-01-13T00:52:17.076+0000] {taskinstance.py:2481} INFO - Exporting env vars: AIRFLOW_CTX_DAG_OWNER='***' AIRFLOW_CTX_DAG_ID='fdic_ncua_data_marts' AIRFLOW_CTX_TASK_ID='trigger_metrics_dag' AIRFLOW_CTX_EXECUTION_DATE='2024-01-13T00:52:16.320019+00:00' AIRFLOW_CTX_TRY_NUMBER='1' AIRFLOW_CTX_DAG_RUN_ID='manual__2024-01-13T00:52:16.320019+00:00'
[2024-01-13T00:52:17.087+0000] {taskinstance.py:2699} ERROR - Task failed with exception
Traceback (most recent call last):
  File "/home/airflow/.local/lib/python3.8/site-packages/airflow/models/taskinstance.py", line 433, in _execute_task
    result = execute_callable(context=context, **execute_callable_kwargs)
  File "/home/airflow/.local/lib/python3.8/site-packages/airflow/operators/trigger_dagrun.py", line 165, in execute
    dag_run = trigger_dag(
  File "/home/airflow/.local/lib/python3.8/site-packages/airflow/api/common/trigger_dag.py", line 122, in trigger_dag
    raise DagNotFound(f"Dag id {dag_id} not found in DagModel")
airflow.exceptions.DagNotFound: Dag id fdic_ncua_metrics not found in DagModel
[2024-01-13T00:52:17.094+0000] {taskinstance.py:1138} INFO - Marking task as FAILED. dag_id=fdic_ncua_data_marts, task_id=trigger_metrics_dag, execution_date=20240113T005216, start_date=20240113T005216, end_date=20240113T005217
[2024-01-13T00:52:17.100+0000] {standard_task_runner.py:107} ERROR - Failed to execute job 210 for task trigger_metrics_dag (Dag id fdic_ncua_metrics not found in DagModel; 13521)
[2024-01-13T00:52:17.115+0000] {local_task_job_runner.py:234} INFO - Task exited with return code 1
[2024-01-13T00:52:17.124+0000] {taskinstance.py:3281} INFO - 0 downstream tasks scheduled from follow-on schedule check
